Workbook

Sheet 100% Insp
A2: Police Officers: JAMES HALL JENNINGS STEPHENS ADAMS Date: __05_ / SEPT/ 25 /
A4: Put a line through police officer(s) name(s) that are not on duty (Example: Fenn) | J4: K-9 Officer(s) present
A6: 100 % Inspection of Commercial Vehicle (Open hood, all exterior doors, compartments, interior compartments, storage boxes)
A7: # | B7: Time | C7: Driver Name | F7: Company Name | J7: Vehicle Registration or Tag # | M7: State
C9: Driver License Number & State | F9: Phone Number | J9: Vehicle VIN #
A11: Driver's Home Address with City & State | F11: Company Address with City & State | J11: Make | K11: Model | L11: Color | M11: Destination
A14: Gender | C14: Race | D14: Height | E14: Weight | F14: Trailer Type (Flat, Box, Dump, Liquid) | J14: TLR Tag # | K14: State | L14: Seal (Y/N) | M14: Seal #
F15: □ Flat | G15: □Dump | H15: □Liquid | I15: □Box
A16: Contraband Found (Yes/No) | E16: Contraband Type | L16: Citation issued
A17: □ Yes □ No | E17: □Pistol □ Rifle □Knife (3" or more) □ Narcotics/Drugs/Pills | L17: □ Yes □ No
E18: □OC Spray □ Billy Club □Stun Gun/Taser □ Explosives
A19: # | B19: Time | C19: Driver Name | F19: Company Name | J19: Vehicle Registration or Tag # | M19: State
C21: Driver License Number & State | F21: Phone Number | J21: Vehicle VIN #
A23: Driver's Home Address with City & State | F23: Company Address with City & State | J23: Make | K23: Model | L23: Color | M23: Destination
A26: Gender | C26: Race | D26: Height | E26: Weight | F26: Trailer Type (Flat, Box, Dump, Liquid) | J26: TLR Tag # | K26: State | L26: Seal (Y/N) | M26: Seal #
F27: □ Flat | G27: □Dump | H27: □Liquid | I27: □Box
A28: Contraband Found (Yes/No) | E28: Contraband Type | L28: Citation issued
A29: □ Yes □ No | E29: □Pistol □ Rifle □Knife (3" or more) □ Narcotics/Drugs/Pills | L29: □ Yes □ No
E30: □OC Spray □ Billy Club □Stun Gun/Taser □ Explosives
A32: Police Officers: JAMES HALL JENNINGS STEPHENS ADAMS Date: __05_ / SEPT/ 25 /
A34: Put a line through police officer(s) name(s) that are not on duty (Example: Fenn) | J34: K-9 Officer(s) present
A36: 100 % Inspection of Commercial Vehicle (Open hood, all exterior doors, compartments, interior compartments, storage boxes)
A37: # | B37: Time | C37: Driver Name | F37: Company Name | J37: Vehicle Registration or Tag # | M37: State
C39: Driver License Number & State | F39: Phone Number | J39: Vehicle VIN #
A41: Driver's Home Address with City & State | F41: Company Address with City & State | J41: Make | K41: Model | L41: Color | M41: Destination
A44: Gender | C44: Race | D44: Height | E44: Weight | F44: Trailer Type (Flat, Box, Dump, Liquid) | J44: TLR Tag # | K44: State | L44: Seal (Y/N) | M44: Seal #
F45: □ Flat | G45: □Dump | H45: □Liquid | I45: □Box
A46: Contraband Found (Yes/No) | E46: Contraband Type | L46: Citation issued
A47: □ Yes □ No | E47: □Pistol □ Rifle □Knife (3" or more) □ Narcotics/Drugs/Pills | L47: □ Yes □ No
E48: □OC Spray □ Billy Club □Stun Gun/Taser □ Explosives
A49: # | B49: Time | C49: Driver Name | F49: Company Name | J49: Vehicle Registration or Tag # | M49: State
C51: Driver License Number & State | F51: Phone Number | J51: Vehicle VIN #
A53: Driver's Home Address with City & State | F53: Company Address with City & State | J53: Make | K53: Model | L53: Color | M53: Destination
A56: Gender | C56: Race | D56: Height | E56: Weight | F56: Trailer Type (Flat, Box, Dump, Liquid) | J56: TLR Tag # | K56: State | L56: Seal (Y/N) | M56: Seal #
F57: □ Flat | G57: □Dump | H57: □Liquid | I57: □Box
A58: Contraband Found (Yes/No) | E58: Contraband Type | L58: Citation issued
A59: □ Yes □ No | E59: □Pistol □ Rifle □Knife (3" or more) □ Narcotics/Drugs/Pills | L59: □ Yes □ No
E60: □OC Spray □ Billy Club □Stun Gun/Taser □ Explosives

Sheet Normal Ops (Comm Veh.) (2)
F1: Inspectors:
F2: Ofc James | H2: Lt Qualls | J2: Ofc Hall | W2: Date: | X2: 46080
F3: Lt Qualls | H3: LCPL BLAIR
N5: K-9/Police present: | P5: NONE
F7: Driver Name | I7: Company Name | M7: Type | O7: Vehicle Registration, State | W7: Number of | X7: Return | Y7: JOE PERRY | AB7: =IFERROR(VLOOKUP(L7,'[1]DATA BASE'!I:Q,3,FALSE),"") | AE7: =IFERROR(VLOOKUP(L7,'[1]DATA BASE'!I:Q,9,FALSE),"") | AG7: =IFERROR(VLOOKUP(L7,'[1]DATA BASE'!I:Q,6,FALSE),"") | AJ7: =VLOOKUP(L7,'[1]DATA BASE'!I:Q,8,FALSE)
A8: # | B8: G, F, R | C8: Occupants | D8: LG/SM | E8: Time | F8: Driver License Number & State | I8: Phone Number | M8: (Circle the type of trailer) | O8: Make, Model, Color | U8: Destination | W8: Returns | X8: Occupants | Y8: =VLOOKUP(L7,'DATA BASE'!B:B,Y9,FALSE) | AB8: =IFERROR(VLOOKUP(L7,'[1]DATA BASE'!I:Q,4,FALSE),"") | AE8: =IFERROR(VLOOKUP(L7,'[1]DATA BASE'!I:Q,5,FALSE),"") | AG8: =IFERROR(VLOOKUP(L7,'[1]DATA BASE'!I:Q,7,FALSE),"")
A9: 1 | B9: G | C9: 2 | D9: LG | E9: *0700 | F9: JOSUHA AMMOS | I9: OXFORD | M9: CONTRACTOR | O9: JN2Y98 GA | U9: GATE 5 | W9: 1 | Y9: DAVID WILDNER | AB9: =IFERROR(VLOOKUP(F9,'DATA BASE'!A:I,3,FALSE),"") | AE9: =IFERROR(VLOOKUP(F9,'DATA BASE'!A:I,9,FALSE),"") | AG9: =IFERROR(VLOOKUP(F9,'DATA BASE'!A:I,6,FALSE),"") | AJ9: =IFERROR(VLOOKUP(F9,'DATA BASE'!A:I,8,FALSE),"")
F10: 070519264 GA | I10: 2294073239 | M10: DUMP | O10: WHITE INTERNATIONAL | Y10: =VLOOKUP(F9,'DATA BASE'!A:I,2,FALSE) | AB10: =IFERROR(VLOOKUP(F9,'DATA BASE'!A:I,4,FALSE),"") | AE10: =IFERROR(VLOOKUP(F9,'DATA BASE'!A:I,5,FALSE),"") | AG10: =IFERROR(VLOOKUP(F9,'DATA BASE'!A:I,7,FALSE),"")
A11: 2 | B11: G | C11: 3 | D11: SM | E11: *0702 | F11: WILLIAMS AARON | I11: OXFORD | M11: CONTRACTOR | O11: SDL8511 GA | U11: GATE 5 | Y11: DAVID WILDNER | AB11: =IFERROR(VLOOKUP(F11,'DATA BASE'!A:I,3,FALSE),"") | AE11: =IFERROR(VLOOKUP(F11,'DATA BASE'!A:I,9,FALSE),"") | AG11: =IFERROR(VLOOKUP(F11,'DATA BASE'!A:I,6,FALSE),"") | AJ11: =IFERROR(VLOOKUP(F11,'DATA BASE'!A:I,8,FALSE),"")
F12: 055944423 GA | I12: 2294073239 | M12: PU | O12: GREEN FORD | Y12: =VLOOKUP(F11,'DATA BASE'!A:I,2,FALSE) | AB12: =IFERROR(VLOOKUP(F11,'DATA BASE'!A:I,4,FALSE),"") | AE12: =IFERROR(VLOOKUP(F11,'DATA BASE'!A:I,5,FALSE),"") | AG12: =IFERROR(VLOOKUP(F11,'DATA BASE'!A:I,7,FALSE),"")
A13: 3 | B13: G | C13: 3 | D13: SM | E13: *0703 | F13: GREG BROCK | I13: TASTY KAKE | M13: COMMERCIAL | O13: GBW501 GA | U13: BASEWIDE | Y13: DAVID WILDNER | AB13: =IFERROR(VLOOKUP(F13,'DATA BASE'!A:I,3,FALSE),"") | AE13: =IFERROR(VLOOKUP(F13,'DATA BASE'!A:I,9,FALSE),"") | AG13: =IFERROR(VLOOKUP(F13,'DATA BASE'!A:I,6,FALSE),"") | AJ13: =IFERROR(VLOOKUP(F13,'DATA BASE'!A:I,8,FALSE),"")
F14: *054614269 GA | I14: 2298547008 | M14: SEMI BOX | O14: FREIGHTLINER, WHITE | Y14: =VLOOKUP(F13,'DATA BASE'!A:I,2,FALSE) | AB14: =IFERROR(VLOOKUP(F13,'DATA BASE'!A:I,4,FALSE),"") | AE14: =IFERROR(VLOOKUP(F13,'DATA BASE'!A:I,5,FALSE),"") | AG14: =IFERROR(VLOOKUP(F13,'DATA BASE'!A:I,7,FALSE),"")
A15: 4 | B15: G | C15: 1 | D15: SM | E15: *0705 | F15: JOSEPH PERRY | I15: EMCO SERVICES | M15: CONTRACTOR | O15: PXQK65 FL | U15: BASEWIDE | W15: 3 | Y15: DAVID WILDNER | AB15: =IFERROR(VLOOKUP(F15,'DATA BASE'!A:I,3,FALSE),"") | AE15: =IFERROR(VLOOKUP(F15,'DATA BASE'!A:I,9,FALSE),"") | AG15: =IFERROR(VLOOKUP(F15,'DATA BASE'!A:I,6,FALSE),"") | AJ15: =IFERROR(VLOOKUP(F15,'DATA BASE'!A:I,8,FALSE),"")
F16: *049722562 GA | I16: 2298696940 | M16: VAN | O16: FORD, WHITE | Y16: =VLOOKUP(F15,'DATA BASE'!A:I,2,FALSE) | AB16: =IFERROR(VLOOKUP(F15,'DATA BASE'!A:I,4,FALSE),"") | AE16: =IFERROR(VLOOKUP(F15,'DATA BASE'!A:I,5,FALSE),"") | AG16: =IFERROR(VLOOKUP(F15,'DATA BASE'!A:I,7,FALSE),"")
A17: 5 | B17: G | C17: 1 | D17: LG | E17: *0709 | F17: DZHUMANOV BOZULAN | I17: NEW TRANS | M17: COMMERCIAL | O17: P1302270 IL | U17: 1221 | Y17: DAVID WILDNER | AB17: =IFERROR(VLOOKUP(F17,'DATA BASE'!A:I,3,FALSE),"") | AE17: =IFERROR(VLOOKUP(F17,'DATA BASE'!A:I,9,FALSE),"") | AG17: =IFERROR(VLOOKUP(F17,'DATA BASE'!A:I,6,FALSE),"") | AJ17: =IFERROR(VLOOKUP(F17,'DATA BASE'!A:I,8,FALSE),"")
F18: Y7912677 CA | I18: 6699462830 | M18: FLAT | O18: BLUE VOLVO | Y18: =VLOOKUP(F17,'DATA BASE'!A:I,2,FALSE) | AB18: =IFERROR(VLOOKUP(F17,'DATA BASE'!A:I,4,FALSE),"") | AE18: =IFERROR(VLOOKUP(F17,'DATA BASE'!A:I,5,FALSE),"") | AG18: =IFERROR(VLOOKUP(F17,'DATA BASE'!A:I,7,FALSE),"")
A19: 6 | B19: F | C19: 1 | D19: LG | E19: *0710 | F19: NATHAN WOODS | I19: COCA COLA | M19: COMMERCIAL | O19: P683CL GA | U19: 7450 | Y19: DAVID WILDNER | AB19: =IFERROR(VLOOKUP(F19,'DATA BASE'!A:I,3,FALSE),"") | AE19: =IFERROR(VLOOKUP(F19,'DATA BASE'!A:I,9,FALSE),"") | AG19: =IFERROR(VLOOKUP(F19,'DATA BASE'!A:I,6,FALSE),"") | AJ19: =IFERROR(VLOOKUP(F19,'DATA BASE'!A:I,8,FALSE),"")
F20: *061070163 GA | I20: 2294720465 | M20: BOX | O20: RED INTERNATIONAL | Y20: =VLOOKUP(F19,'DATA BASE'!A:I,2,FALSE) | AB20: =IFERROR(VLOOKUP(F19,'DATA BASE'!A:I,4,FALSE),"") | AE20: =IFERROR(VLOOKUP(F19,'DATA BASE'!A:I,5,FALSE),"") | AG20: =IFERROR(VLOOKUP(F19,'DATA BASE'!A:I,7,FALSE),"")
A21: 7 | B21: G | C21: 1 | D21: SM | E21: *0712 | F21: THOMAS CAMP | I21: GTPC | M21: CONTRACTOR | O21: 6EH0777 MD | U21: BASEWIDE | Y21: DAVID WILDNER | AB21: =IFERROR(VLOOKUP(F21,'DATA BASE'!A:I,3,FALSE),"") | AE21: =IFERROR(VLOOKUP(F21,'DATA BASE'!A:I,9,FALSE),"") | AG21: =IFERROR(VLOOKUP(F21,'DATA BASE'!A:I,6,FALSE),"") | AJ21: =IFERROR(VLOOKUP(F21,'DATA BASE'!A:I,8,FALSE),"")
F22: *052037364 GA | I22: 8009490223 | M22: PU | O22: CHEVY, WHITE | Y22: =VLOOKUP(F21,'DATA BASE'!A:I,2,FALSE) | AB22: =IFERROR(VLOOKUP(F21,'DATA BASE'!A:I,4,FALSE),"") | AE22: =IFERROR(VLOOKUP(F21,'DATA BASE'!A:I,5,FALSE),"") | AG22: =IFERROR(VLOOKUP(F21,'DATA BASE'!A:I,7,FALSE),"")
A23: 8 | B23: G | C23: 1 | D23: SM | E23: *0713 | F23: DONNIE BURLSON | I23: ACE TECH | M23: CONTRACTOR | O23: DAT4681 GA | U23: BASEWIDE | W23: 2 | Y23: DAVID WILDNER | AB23: =IFERROR(VLOOKUP(F23,'DATA BASE'!A:I,3,FALSE),"") | AE23: =IFERROR(VLOOKUP(F23,'DATA BASE'!A:I,9,FALSE),"") | AG23: =IFERROR(VLOOKUP(F23,'DATA BASE'!A:I,6,FALSE),"") | AJ23: =IFERROR(VLOOKUP(F23,'DATA BASE'!A:I,8,FALSE),"")
F24: *053671480 GA | I24: 2292446412 | M24: PU | O24: RED FORD | Y24: =VLOOKUP(F23,'DATA BASE'!A:I,2,FALSE) | AB24: =IFERROR(VLOOKUP(F23,'DATA BASE'!A:I,4,FALSE),"") | AE24: =IFERROR(VLOOKUP(F23,'DATA BASE'!A:I,5,FALSE),"") | AG24: =IFERROR(VLOOKUP(F23,'DATA BASE'!A:I,7,FALSE),"")
A25: 9 | B25: G | C25: 1 | D25: SM | E25: *0741 | F25: JAMES ROWE | I25: ACE TECH | M25: CONTRACTOR | O25: DAT4680 GA | U25: BASEWIDE | Y25: DAVID WILDNER | AB25: =IFERROR(VLOOKUP(F25,'DATA BASE'!A:I,3,FALSE),"") | AE25: =IFERROR(VLOOKUP(F25,'DATA BASE'!A:I,9,FALSE),"") | AG25: =IFERROR(VLOOKUP(F25,'DATA BASE'!A:I,6,FALSE),"") | AJ25: =IFERROR(VLOOKUP(F25,'DATA BASE'!A:I,8,FALSE),"")
F26: *053081838 GA | I26: 2292446412 | M26: PU | O26: RED FORD | Y26: =VLOOKUP(F25,'DATA BASE'!A:I,2,FALSE) | AB26: =IFERROR(VLOOKUP(F25,'DATA BASE'!A:I,4,FALSE),"") | AE26: =IFERROR(VLOOKUP(F25,'DATA BASE'!A:I,5,FALSE),"") | AG26: =IFERROR(VLOOKUP(F25,'DATA BASE'!A:I,7,FALSE),"")
A27: 10 | B27: G | C27: 2 | D27: LG | E27: *0748 | F27: CALEB CROSBY | I27: RYDER | M27: COMMERCIAL | O27: 2833418 IN | U27: 1260 | Y27: DAVID WILDNER | AB27: =IFERROR(VLOOKUP(F27,'DATA BASE'!A:I,3,FALSE),"") | AE27: =IFERROR(VLOOKUP(F27,'DATA BASE'!A:I,9,FALSE),"") | AG27: =IFERROR(VLOOKUP(F27,'DATA BASE'!A:I,6,FALSE),"") | AJ27: =IFERROR(VLOOKUP(F27,'DATA BASE'!A:I,8,FALSE),"")
F28: 9426017 AL | I28: 3342968917 | M28: BOX | O28: WHITE INTERNATIONAL | Y28: =VLOOKUP(F27,'DATA BASE'!A:I,2,FALSE) | AB28: =IFERROR(VLOOKUP(F27,'DATA BASE'!A:I,4,FALSE),"") | AE28: =IFERROR(VLOOKUP(F27,'DATA BASE'!A:I,5,FALSE),"") | AG28: =IFERROR(VLOOKUP(F27,'DATA BASE'!A:I,7,FALSE),"")
A29: 11 | B29: G | C29: 1 | D29: LG | E29: *0751 | F29: WILLIAM PROCTOR | I29: YK EXPRESS | M29: COMMERICAL | O29: XE821S FL | U29: 1221 | Y29: DAVID WILDNER | AB29: =IFERROR(VLOOKUP(F29,'DATA BASE'!A:I,3,FALSE),"") | AE29: =IFERROR(VLOOKUP(F29,'DATA BASE'!A:I,9,FALSE),"") | AG29: =IFERROR(VLOOKUP(F29,'DATA BASE'!A:I,6,FALSE),"") | AJ29: =IFERROR(VLOOKUP(F29,'DATA BASE'!A:I,8,FALSE),"")
F30: P608784099000 FL | I30: 9418304769 | M30: FLAT | O30: BLACK PETERBILT | Y30: =VLOOKUP(F29,'DATA BASE'!A:I,2,FALSE) | AB30: =IFERROR(VLOOKUP(F29,'DATA BASE'!A:I,4,FALSE),"") | AE30: =IFERROR(VLOOKUP(F29,'DATA BASE'!A:I,5,FALSE),"") | AG30: =IFERROR(VLOOKUP(F29,'DATA BASE'!A:I,7,FALSE),"")
A31: 12 | B31: F | C31: 1 | D31: LG | E31: *0753 | F31: WILLIAM COPELAND | I31: CONCRETE ENTERP | M31: COMMERCIAL | O31: GK1878 GA | U31: KENNELS | Y31: DAVID WILDNER | AB31: =IFERROR(VLOOKUP(F31,'DATA BASE'!A:I,3,FALSE),"") | AE31: =IFERROR(VLOOKUP(F31,'DATA BASE'!A:I,9,FALSE),"") | AG31: =IFERROR(VLOOKUP(F31,'DATA BASE'!A:I,6,FALSE),"") | AJ31: =IFERROR(VLOOKUP(F31,'DATA BASE'!A:I,8,FALSE),"")
F32: *055172180 GA | I32: 2298811904 | M32: CONCRETE | O32: GREEN WESTERN | Y32: =VLOOKUP(F31,'DATA BASE'!A:I,2,FALSE) | AB32: =IFERROR(VLOOKUP(F31,'DATA BASE'!A:I,4,FALSE),"") | AE32: =IFERROR(VLOOKUP(F31,'DATA BASE'!A:I,5,FALSE),"") | AG32: =IFERROR(VLOOKUP(F31,'DATA BASE'!A:I,7,FALSE),"")
A33: 13 | B33: G | C33: 1 | D33: LG | E33: *0754 | F33: BRYAN MICHAEL | I33: SIEMENS | M33: COMMERCIAL | O33: DR44TK FL | U33: 2200 | Y33: DAVID WILDNER | AB33: =IFERROR(VLOOKUP(F33,'DATA BASE'!A:I,3,FALSE),"") | AE33: =IFERROR(VLOOKUP(F33,'DATA BASE'!A:I,9,FALSE),"") | AG33: =IFERROR(VLOOKUP(F33,'DATA BASE'!A:I,6,FALSE),"") | AJ33: =IFERROR(VLOOKUP(F33,'DATA BASE'!A:I,8,FALSE),"")
F34: B650544873820 FL | I34: 8008920288 | M34: SUV | O34: WHITE EQUINOX | Y34: =VLOOKUP(F33,'DATA BASE'!A:I,2,FALSE) | AB34: =IFERROR(VLOOKUP(F33,'DATA BASE'!A:I,4,FALSE),"") | AE34: =IFERROR(VLOOKUP(F33,'DATA BASE'!A:I,5,FALSE),"") | AG34: =IFERROR(VLOOKUP(F33,'DATA BASE'!A:I,7,FALSE),"")
A35: 14 | B35: G | C35: 1 | D35: LG | E35: *0756 | F35: TORRANCE LAWRENCE | I35: SPARTAN NASH | M35: COMMERICAL | O35: 424423 NE | U35: 7500 | Y35: DAVID WILDNER | AB35: =IFERROR(VLOOKUP(F35,'DATA BASE'!A:I,3,FALSE),"") | AE35: =IFERROR(VLOOKUP(F35,'DATA BASE'!A:I,9,FALSE),"") | AG35: =IFERROR(VLOOKUP(F35,'DATA BASE'!A:I,6,FALSE),"") | AJ35: =IFERROR(VLOOKUP(F35,'DATA BASE'!A:I,8,FALSE),"")
F36: 072479857 GA | I36: 3345409441 | M36: BOX | O36: WHITE INTERNATIONAL | Y36: =VLOOKUP(F35,'DATA BASE'!A:I,2,FALSE) | AB36: =IFERROR(VLOOKUP(F35,'DATA BASE'!A:I,4,FALSE),"") | AE36: =IFERROR(VLOOKUP(F35,'DATA BASE'!A:I,5,FALSE),"") | AG36: =IFERROR(VLOOKUP(F35,'DATA BASE'!A:I,7,FALSE),"")
A37: 15 | B37: G | C37: 1 | D37: LG | E37: *0758 | F37: TIMOTHY WALKER | I37: EXPRESS DISPOSAL | M37: CONTRACTOR | O37: YHE502 GA | U37: BASEWIDE | Y37: DAVID WILDNER | AB37: =IFERROR(VLOOKUP(F37,'DATA BASE'!A:I,3,FALSE),"") | AE37: =IFERROR(VLOOKUP(F37,'DATA BASE'!A:I,9,FALSE),"") | AG37: =IFERROR(VLOOKUP(F37,'DATA BASE'!A:I,6,FALSE),"") | AJ37: =IFERROR(VLOOKUP(F37,'DATA BASE'!A:I,8,FALSE),"")
F38: *058791327 GA | I38: 2293524300 | M38: TANK | O38: WHITE INTER | Y38: =VLOOKUP(F37,'DATA BASE'!A:I,2,FALSE) | AB38: =IFERROR(VLOOKUP(F37,'DATA BASE'!A:I,4,FALSE),"") | AE38: =IFERROR(VLOOKUP(F37,'DATA BASE'!A:I,5,FALSE),"") | AG38: =IFERROR(VLOOKUP(F37,'DATA BASE'!A:I,7,FALSE),"")
A39: 16 | B39: G | C39: 1 | D39: LG | E39: *0803 | F39: ALVIN CONLEY | I39: DAVENPORT | M39: COMMERCIAL | O39: YDR952 GA | U39: BASEWIDE | Y39: DAVID WILDNER | AB39: =IFERROR(VLOOKUP(F39,'DATA BASE'!A:I,3,FALSE),"") | AE39: =IFERROR(VLOOKUP(F39,'DATA BASE'!A:I,9,FALSE),"") | AG39: =IFERROR(VLOOKUP(F39,'DATA BASE'!A:I,6,FALSE),"") | AJ39: =IFERROR(VLOOKUP(F39,'DATA BASE'!A:I,8,FALSE),"")
F40: *050551154 GA | I40: 2294461541 | M40: BOX | O40: ISUZU, WHITE | Y40: =VLOOKUP(F39,'DATA BASE'!A:I,2,FALSE) | AB40: =IFERROR(VLOOKUP(F39,'DATA BASE'!A:I,4,FALSE),"") | AE40: =IFERROR(VLOOKUP(F39,'DATA BASE'!A:I,5,FALSE),"") | AG40: =IFERROR(VLOOKUP(F39,'DATA BASE'!A:I,7,FALSE),"")
A41: 17 | B41: G | C41: 1 | D41: LG | E41: *0820 | F41: TYRONE PITTS | I41: KLB | M41: COMMERCIAL | O41: XE820Y FL | U41: 7500 | Y41: DAVID WILDNER | AB41: =IFERROR(VLOOKUP(F41,'DATA BASE'!A:I,3,FALSE),"") | AE41: =IFERROR(VLOOKUP(F41,'DATA BASE'!A:I,9,FALSE),"") | AG41: =IFERROR(VLOOKUP(F41,'DATA BASE'!A:I,6,FALSE),"") | AJ41: =IFERROR(VLOOKUP(F41,'DATA BASE'!A:I,8,FALSE),"")
F42: P320800774 FL | I42: 8509803664 | M42: BOX | O42: TAN PETERBILT | Y42: =VLOOKUP(F41,'DATA BASE'!A:I,2,FALSE) | AB42: =IFERROR(VLOOKUP(F41,'DATA BASE'!A:I,4,FALSE),"") | AE42: =IFERROR(VLOOKUP(F41,'DATA BASE'!A:I,5,FALSE),"") | AG42: =IFERROR(VLOOKUP(F41,'DATA BASE'!A:I,7,FALSE),"")
...

Sheet DATA BASE
A1: DRIVER NAME DRIVER | B1: LICENCE NUMBER AND STATE | C1: COMPANY NAME | D1: PHONE NUMBER | E1: TYPE | F1: VEHICLE REGISTRATION, STATE | G1: MAKE MODEL COLOR | H1: DESTINATION | I1: TYPE
A11: STEPHEN COOK | B11: 051737078 GA | C11: A WEST | D11: 2298888347 | E11: PU | F11: DBF4190 GA | G11: CHEVY, WHITE | H11: BASEWIDE | I11: CONTRACTOR
A12: FRANK GRIFFIN | B12: *049722562 GA | C12: EMCO SERVICES | D12: 8505144822 | E12: VAN | F12: PXQK65 FL | G12: FORD, WHITE | H12: BASEWIDE | I12: CONTRACTOR
A13: THOMAS CAMP | B13: *052037364 GA | C13: GTPC | D13: 8009490223 | E13: PU | F13: 6EH0777 MD | G13: CHEVY, WHITE | H13: BASEWIDE | I13: CONTRACTOR
A14: CHRIS SMITH | B14: *055371195 GA | C14: S&S CONCRETE | D14: 2294388566 | E14: PU | F14: SSCRET7 GA | G14: DODGE, WHITE | H14: 1330 | I14: CONTRACTOR
A15: DONALD LOWE | B15: *052635058 GA | C15: S&S CONCRETE | D15: 2294388566 | E15: DUMP | F15: EBJ071 GA | G15: FREIGHTLINER, WHITE | H15: BASEWIDE | I15: COMMERCIAL
A16: GREG BROCK | B16: *054614269 GA | C16: TASTY KAKE | D16: 2298547008 | E16: SEMI BOX | F16: GBW501 GA | G16: FREIGHTLINER, WHITE | H16: BASEWIDE | I16: COMMERCIAL
A17: SCOTT GILMER | B17: *049894146 GA | C17: ALBANY AIR | D17: 2294360341 | E17: PU | F17: CSE7190 GA | G17: FORD, WHITE | H17: 1210 | I17: CONTRACTOR
A18: KHALIF COLLIER | B18: *052140621 GA | C18: JB MASONRY | D18: 2294180828 | E18: SUV | F18: SPDWAGN GA | G18: CHEVY, GREEN | H18: KENNELS | I18: CONTRACTOR
A19: CALVIN CATON | B19: *051354218 GA | C19: A WEST | D19: 2298888347 | E19: PU | F19: CIZ5500 GA | G19: CHEVY, WHITE | H19: BASEWIDE | I19: CONTRACTOR
A20: DAVID WIDNER | B20: *057894921 GA | C20: RHC | D20: 2294353500 | E20: PU | F20: PLX3051 GA | G20: FORD, SILVER | H20: HOUSING | I20: CONTRACTOR
A21: KELVONTE JONES | B21: *053008698 GA | C21: SPARTAN NASH | D21: 7063290642 | E21: SEMI BOX | F21: 223642 NE | G21: INTERNATIONAL, WHITE | H21: 7501 | I21: COMMERCIAL
A22: DAVID ROGERS | B22: *058937219 GA | C22: SEPTIC PLUMBING | D22: 2294325376 | E22: BOX SEMI | F22: CXD2341 GA | G22: FORD, WHITE | H22: KENNELS | I22: CONTRACTOR
A23: FRANK GRIFFIN | B23: *055499949 GA | C23: ADAMS EXTERMINATOR | D23: 2298943420 | E23: VAN | F23: RUQ7451 GA | G23: NISSAN, WHITE | H23: HOUSING | I23: CONTRACTOR
A24: WILLIAM BOREFIELD | B24: *050951758 GA | C24: ALBANY BEVERAGE | D24: 2298811092 | E24: VAN | F24: CPU1706 GA | G24: FORD, WHITE | H24: 7500 | I24: CONTRACTOR
A25: VERNON COOK | B25: *055782627 GA | C25: CONCRETE ENTERPRISE | D25: 2298881104 | E25: CEMENT | F25: GAI103 GA | G25: MACK, GREEN | H25: GOLF COURSE | I25: COMMERCIAL
A26: JEFFREY JONES | B26: *056016504 GA | C26: RHC | D26: 2298889896 | E26: PU | F26: RDQ2218 GA | G26: FORD, RED | H26: HOUSING | I26: CONTRACTOR
A27: WILLIAM SHIVER | B27: *055739155 GA | C27: GEM | D27: 2298812598 | E27: PU | F27: RJT8950 GA | G27: CHEVY, BLACK | H27: BASEWIDE | I27: CONTRACTOR
A28: ROBERT ANDREWS | B28: *007795096 GA | C28: ESTES | D28: 2298943567 | E28: SEMI BOX | F28: 3585749 IN | G28: FREIGHTLINER, YELLOW | H28: 1221 | I28: COMMERCIAL
A29: DONALD SPILLERS | B29: *051592125 GA | C29: SUNBELT | D29: 2298865406 | E29: SEMI BOX | F29: P1249373 IL | G29: FREIGHTLINER, GREEN | H29: 1221 | I29: COMMERCIAL
A30: PATRICK RICHARDSON | B30: *053987739 GA | C30: ACT | D30: 2296032516 | E30: SEMI BOX | F30: R675615 TX | G30: FREIGHTLINER, BLUE | H30: 1221 | I30: COMMERCIAL
A31: ALLEN HAMPTON | B31: H366459920000 FL | C31: 1ST COAST CARGO | D31: 8447312137 | E31: SEMI BOX | F31: 3603944 IN | G31: FREIGHTLINER, WHITE | H31: 1221 | I31: COMMERCIAL
A32: DONNIE ULMER | B32: *055999972 GA | C32: SUNBELT | D32: 2293643984 | E32: SEMI BOX | F32: P21081932 IL | G32: FREIGHTLINER, GREEN | H32: 1221 | I32: COMMERCIAL
A33: MASON PEEPLES | B33: *057537613 GA | C33: S&S CONCRETE | D33: 2294388566 | E33: PU | F33: SSCRET2 GA | G33: DODGE, WHITE | H33: BASEWIDE | I33: CONTRACTOR
A34: SHUMONICA GRAHAM | B34: *051938874 GA | C34: DHL | D34: 2294857833 | E34: VAN | F34: 48797ND GA | G34: FORD, YELLOW | H34: 1221 | I34: CONTRACTOR
A35: JEFF FOWLER | B35: *054094646 GA | C35: S&S CONCRETE | D35: 2294388566 | E35: PU | F35: TCG0009 GA | G35: DODGE, WHITE | H35: 1221 | I35: CONTRACTOR
A36: MONTAVIOUS BUCHANAN | B36: *056819454 GA | C36: BUCHANAN SECURITY | D36: 2295663392 | E36: VAN | F36: SBR9305 GA | G36: FORD, WHITE | H36: 7000 | I36: CONTRACTOR
A37: CRAIG GILLIS | B37: 5819417 AL | C37: GA POWER | D37: 4045203683 | E37: PU | F37: CSC7473 GA | G37: FORD, WHITE | H37: SOLAR PANELS | I37: CONTRACTOR
A38: COPELAND MAX | B38: *032829415 GA | C38: SAIA | D38: 2295075148 | E38: SEMI BOX | F38: P253486 LA | G38: FREIGHTLINER, RED | H38: 1221 | I38: COMMERCIAL
A39: JOHN PRICE | B39: *054307270 GA | C39: UNIFIRST | D39: 2299390536 | E39: PU | F39: EJF362 GA | I39: CONTRACTOR
A40: DARRYL SLAUGHTER | B40: *051217687 GA | C40: US FOODS | D40: 2292885451 | E40: SEMI BOX | F40: 3047668 IN | G40: FREIGHTLINER, WHITE | H40: 7501 | I40: COMMERCIAL
A41: STEVE COOK | B41: *051737078 GA | C41: A WEST | D41: 2298888347 | E41: PU | F41: DBF4190 GA | G41: CHEVY, WHITE | H41: BASEWIDE | I41: CONTRACTOR
A42: ALEJO MENDEZ | B42: *051215374 GA | C42: METRO POWER | D42: 4782448291 | E42: PU | F42: RDB6220 GA | G42: CHEVY, WHITE | H42: FIRESTATION | I42: CONTRACTOR
A43: CHAD PINTO | B43: *007414511 SC | C43: MITCHELL BROTHER | D43: 8432717308 | E43: PU | F43: P892296 SC | G43: GMC, WHITE | H43: 7360 | I43: CONTRACTOR
A44: DONALD FREY | B44: *056476644 GA | C44: S&S CONCRETE | D44: 2294388566 | E44: PU | F44: SSCRET6 GA | G44: DODGE, WHITE | H44: 7360 | I44: CONTRACTOR
A45: WILLIAM DANIEL | B45: *053918006 GA | C45: MISSION FOODS | D45: 6786728923 | E45: PU | F45: EEG625 GA | G45: DODGE, RED | H45: 7501 | I45: CONTRACTOR
A46: SAZI ERCAN | B46: *058316658 GA | C46: FAST TRANSP. | D46: 4158810909 | E46: SEMI BOX | F46: C747ES GA | G46: VOLVO, BLUE | H46: 1221 | I46: COMMERCIAL
A47: LEON CANNON | B47: 6844300 AL | C47: LANDSTAR | D47: 2052606016 | E47: SEMI BOX | F47: 3400037 IN | G47: FREIGHTLINER, YELL | H47: 1221 | I47: COMMERCIAL
A48: ALVIN CONLEY | B48: *050551154 GA | C48: DAVENPORT | D48: 2294461541 | E48: BOX | F48: YDR952 GA | G48: ISUZU, WHITE | H48: BASEWIDE | I48: COMMERCIAL
A49: LONDON FRAZIER | B49: *06084146 GA | C49: FEDEX | D49: 2292964982 | E49: BOX | F49: AR07IK FL | G49: WHITE FORD | H49: BASEWIDE | I49: CONTRACTOR
...

Sheet Daily Stat Report (2)
A1: Commercial Vehicle Entrance (Gate 5/15) Daily Stat Report
B3: Line | C3: Log | F3: # of vehicles | I3: Date: | J3: 46080
B5: Line 1 | C5: Large Trucks (Semi, Dump Trucks) | G5: {=COUNTIF('Normal Ops (Comm Veh.) (2)'!D9:D410,"LG") + SUMPRODUCT(('Normal Ops (Comm Veh.) (2)'!D9:D410="LG")*IFERROR('Normal Ops (Comm Veh.) (2)'!W9:W410,0))} | I5: 1408's | J5: 0
B7: Line 2 | C7: Small Veh. (Contr.) | G7: {=COUNTIF('Normal Ops (Comm Veh.) (2)'!D9:D410,"SM") + SUMPRODUCT(('Normal Ops (Comm Veh.) (2)'!D9:D410="SM")*IFERROR('Normal Ops (Comm Veh.) (2)'!W9:W410,0))} | I7: CCN's | J7: 0
B9: Line 4 | C9: G Inspections | G9: =COUNTIF('Normal Ops (Comm Veh.) (2)'!B9:B410,"G")
B11: Line 5 | C11: F Inspections | G11: =COUNTIF('Normal Ops (Comm Veh.) (2)'!B9:B410,"F")
B13: Line 6 | C13: R Inspections | G13: =COUNTIF('Normal Ops (Comm Veh.) (2)'!B9:B410,"R")
B15: Line 7 | C15: Individual processed threw the Gate | G15: =SUM('Normal Ops (Comm Veh.) (2)'!C9:C410,'Normal Ops (Comm Veh.) (2)'!X9:X410)
B17: Line 8 | C17: Number of returns | G17: =SUM('Normal Ops (Comm Veh.) (2)'!W9:W410)
B19: 2200 | G19: Total CVs Inspected | J19: =SUM(G5,G7)
G20: (Total of lines 1+2+8)
B21: Officers on Duty :
E22: Lt Qualls | F22: LCPL BIERY | H22: CPL JOHNSON
E23: Ofc Hall | F23: Ofc James
B24: Desk Sgt on duty who received CVI totals: | G24: Sgt Lyons
C26: ** Turn in this daily stat sheet with the daily logs **

Sheet LOG DETAILS
A1: LOG DATE | B1: 2026-03-03
A3: ENTRY TIME UTC | B3: ENTRY TIME | C3: DRIVER | D3: COMPANY | E3: VEHICLE | F3: INSPECTION TYPE | G3: SCAN TOKEN | H3: NOTES
